Workbook

Sheet Rebuild Summary
A1: PO Box 13012 Calgary RPO Beltline, AB T2R 1C6 info@luminovas.ca Phone: 587-320-0261
A2: WYNDHAM CROSSING B BUILDING - ABATEMENT | G2: 40762.51
B3: TOTAL
A4: TOTAL - NOT INCLUDING GST | B4: 115250
A6: WYNDHAM CROSSING B BUILDING REBUILD UNITS
B7: TOTAL | C7: UNITS | D7: AVG $/UNIT
A8: BASE SCOPE REBUILD - SEE DETAILED BREAK DOWN | B8: ='Pricing Units Insurance'!E81 -> 0 | C8: 29 | D8: =B8/C8 -> 0
A9: OPTIONAL UPGRADES - SEE DETAILED BREAK DOWN | B9: =#REF! -> #REF! | C9: 29 | D9: =B9/C9 -> #REF!
A10: TOTAL - NOT INCLUDING GST | B10: =SUM(B8:B9) -> #REF! | C10: 29 | D10: =B10/C10 -> #REF! | G10: 692510
G11: 1338420.4
A12: WYNDHAM CROSSING B BUILDING COMMON AREAS | G12: 40762.51
B13: TOTAL
A14: LAUNDRY ROOM - SEE DETAILED BREAK DOWN | B14: =#REF! -> #REF!
A15: STORAGE ROOM - SEE DETAILED BREAK DOWN | B15: =#REF! -> #REF!
A16: HALLWAYS & STAIRWELLS - SEE DETAILED BREAK DOWN | B16: =#REF! -> #REF!
A17: OPTIONAL UPGRADES (REMAINING CEILING TILES) | B17: =ROUNDUP(2889*0.7*40/2/4,2) -> 10111.5 | G17: 115250
A18: TOTAL - NOT INCLUDING GST | B18: =SUM(B14:B16) -> #REF! | G18: =132500/2 -> 66250
G19: 199240.03
A20: TOTAL PROJECT SUMMARY | G20: 35000
B21: CHARGE | C21: COST | D21: PROFIT | G21: 25000
A22: UNITS - BASE SCOPE | B22: =B8 -> 0 | C22: ='Pricing Units Insurance'!#REF! -> #REF! | D22: =B22-C22 -> #REF! | G22: =SUM(G17:G21) -> 440740.03
A23: ABATEMENT | B23: =B4 -> 115250 | C23: 115250 | D23: =B23-C23 -> 0
A24: UNIT UPGRADES | B24: =B9 -> #REF! | C24: =#REF! -> #REF! | D24: =B24-C24 -> #REF!
A25: COMMON AREAS | B25: =B18 -> #REF! | C25: =#REF!+#REF!+#REF! -> #REF! | D25: =B25-C25 -> #REF!
A26: GRAND TOTAL - NOT INCLUDING GST | B26: =SUM(B22:B25) -> #REF! | C26: =SUM(C22:C25) -> #REF! | D26: =SUM(D22:D25) -> #REF!
D27: =D26/B26 -> #REF!
B30: =0.35*B26 -> #REF!
B31: =B30*2 -> #REF!
A35: DESCIPTION | B35: COST
A36: UNIT 1101 | B36: ='Pricing Units Insurance'!D3 -> 63444.02
A37: UNIT 1001 | B37: ='Pricing Units Insurance'!F3 -> 60498.912
A38: UNIT 901 | B38: ='Pricing Units Insurance'!H3 -> 55749.615
A39: UNIT 801 | B39: ='Pricing Units Insurance'!#REF! -> #REF!
A40: UNIT 701 | B40: ='Pricing Units Insurance'!#REF! -> #REF!
A41: EXTERIOR UNIT 1101 AND 1001 | B41: =SUM('Pricing Units Insurance'!#REF!) -> #REF!
A42: HALLWAYS | B42: =SUM('Pricing Units Insurance'!E89:E94) -> 32304
A43: OFFICE | B43: =SUM('Pricing Units Insurance'!E108:E109) -> 11572.5
A44: BOILER ROOM AND ADJACENT HALLWAY | B44: =SUM('Pricing Units Insurance'!#REF!) -> #REF!
A45: Grand Total not including GST | B45: =SUM(B36:B44) -> #REF!

Sheet Pricing Units Insurance
A1: 500 4th Avenue Suite 2500 Calgary , AB T2P 2V6 info@luminovas.ca Phone: 587-320-0261
D2: 3 BED | F2: 2 BED | H2: 1 BED
D3: =SUM(E6:E80) -> 63444.02 | F3: =SUM(G6:G80) -> 60498.912 | H3: =SUM(I6:I80) -> 55749.615
B4: UNIT | C4: RATE | D4: QTY | E4: TOTAL | F4: QTY | G4: TOTAL | H4: QTY | I4: TOTAL | K4: no interior doors
A5: DRYWALL | E5: =TEXT((SUM(E6:E7)),"$0,000.00") -> $14,260.00 | G5: =TEXT((SUM(G6:G7)),"$0,000.00") -> $12,566.70 | I5: =TEXT((SUM(I6:I7)),"$0,000.00") -> $11,022.50
A6: Mud and tape walls | B6: LN FT | C6: 22 | D6: 322 | E6: =$C6*D6 -> 7084 | F6: 288 | G6: =$C6*F6 -> 6336 | H6: 236 | I6: =$C6*H6 -> 5192 | L6: 35401.71 | M6: just insurance
A7: Drywalled Ceiling including Insulation Texture Ceiling | B7: SQFT | C7: 6.9 | D7: 1040 | E7: =$C7*D7 -> 7176 | F7: 903 | G7: =$C7*F7 -> 6230.7 | H7: 845 | I7: =$C7*H7 -> 5830.5 | L7: 40769.71 | M7: new doors, new bathroom (keep bathtub and existing tile)
A8: FINISHING | E8: =TEXT((SUM(E9:E21)),"$0,000.00") -> $9,312.20 | G8: =TEXT((SUM(G9:G21)),"$0,000.00") -> $7,922.50 | I8: =TEXT((SUM(I9:I21)),"$0,000.00") -> $6,237.50
A9: Closet Shelves and Rod (Price per closet/storage room) | B9: EACH | C9: 185 | D9: 6 | E9: =$C9*D9 -> 1110 | F9: 4 | G9: =$C9*F9 -> 740 | H9: 3 | I9: =$C9*H9 -> 555
A10: Doors | B10: EACH | C10: 450 | D10: 5 | E10: =$C10*D10 -> 2250 | F10: 5 | G10: =$C10*F10 -> 2250 | H10: 4 | I10: =$C10*H10 -> 1800
A11: New 20 min fire rated Entry Suite Door | B11: EACH | C11: 1250 | D11: 0 | E11: =$C11*D11 -> 0 | F11: 0 | G11: =$C11*F11 -> 0 | H11: 0 | I11: =$C11*H11 -> 0
A12: Towel bar, toilet paper holder and shower rod | B12: EACH | C12: 190 | D12: 1 | E12: =$C12*D12 -> 190 | F12: 1 | G12: =$C12*F12 -> 190 | H12: 1 | I12: =$C12*H12 -> 190
A13: Door Hardware (handle, hinges, and door stops) | B13: EACH | C13: 95 | D13: 5 | E13: =$C13*D13 -> 475 | F13: 5 | G13: =$C13*F13 -> 475 | H13: 3 | I13: =$C13*H13 -> 285
A14: Mirror | B14: EACH | C14: 200 | D14: 1 | E14: =$C14*D14 -> 200 | F14: 1 | G14: =$C14*F14 -> 200 | H14: 1 | I14: =$C14*H14 -> 200
A15: Closet Doors - Bypass upto 48"W and bifolds upto 36"W | B15: EACH | C15: 350 | D15: 4 | E15: =$C15*D15 -> 1400 | F15: 2 | G15: =$C15*F15 -> 700 | H15: 1 | I15: =$C15*H15 -> 350
A16: Closet Doors - Bypass over 48"W - upto 60"W | B16: EACH | C16: 480 | D16: 0 | E16: =$C16*D16 -> 0 | F16: 0 | G16: =$C16*F16 -> 0 | H16: 0 | I16: =$C16*H16 -> 0
A17: Closet Doors - Bypass over 60"W - upto 72"W | B17: EACH | C17: 490 | D17: 0 | E17: =$C17*D17 -> 0 | F17: 0 | G17: =$C17*F17 -> 0 | H17: 0 | I17: =$C17*H17 -> 0
A18: Closet Doors - Bypass over 72"W - upto 96"W | B18: EACH | C18: 525 | D18: 1 | E18: =$C18*D18 -> 525 | F18: 1 | G18: =$C18*F18 -> 525 | H18: 1 | I18: =$C18*H18 -> 525
A19: Suite Door Closer | B19: EACH | C19: 250 | D19: 1 | E19: =$C19*D19 -> 250 | F19: 1 | G19: =$C19*F19 -> 250 | H19: 1 | I19: =$C19*H19 -> 250
A20: Baseboards MDF as per Spec | B20: LN FT | C20: 4 | D20: =322*1.15 -> 370.3 | E20: =$C20*D20 -> 1481.2 | F20: =ROUNDUP(288*1.15,0) -> 332 | G20: =$C20*F20 -> 1328 | H20: =ROUNDUP(236*1.15,0) -> 272 | I20: =$C20*H20 -> 1088
A21: Window and Door Casing | B21: LN FT | C21: 4.5 | D21: =(54+211)*1.2 -> 318 | E21: =$C21*D21 -> 1431 | F21: =ROUNDUP((210+26+8)*1.15,0) -> 281 | G21: =$C21*F21 -> 1264.5 | H21: =ROUNDUP((175+12+5)*1.15,0) -> 221 | I21: =$C21*H21 -> 994.5
A22: FLOORING | E22: =TEXT((SUM(E23:E25)),"$0,000.00") -> $5,071.32 | G22: =TEXT((SUM(G23:G25)),"$0,000.00") -> $4,235.51 | I22: =TEXT((SUM(I23:I25)),"$0,000.00") -> $3,714.62
A23: Floor Vinyl | B23: SQFT | C23: 4.85 | D23: =40*9*1.15 -> 414 | E23: =$C23*D23 -> 2007.9 | F23: =35*1.15*9 -> 362.25 | G23: =$C23*F23 -> 1756.9125 | H23: =(19+55)*1.15*9 -> 765.9 | I23: =$C23*H23 -> 3714.615
A24: Removal of existing flooring and disposal | B24: SQFT | C24: 0.75 | D24: 0 | E24: =$C24*D24 -> 0 | F24: 0 | G24: =$C24*F24 -> 0 | H24: 0 | I24: =$C24*H24 -> 0
A25: Carpet with underlay | B25: SQFT | C25: 4.5 | D25: =62*9*1.22 -> 680.76 | E25: =$C25*D25 -> 3063.42 | F25: =51*1.2*9 -> 550.8 | G25: =$C25*F25 -> 2478.6 | H25: 0 | I25: =$C25*H25 -> 0
A26: TILING | E26: =TEXT((SUM(E27:E29)),"$0,000.00") -> $0,350.00 | G26: =TEXT((SUM(G27:G29)),"$0,000.00") -> $0,350.00 | I26: =TEXT((SUM(I27:I29)),"$0,000.00") -> $0,350.00
A27: Tile Tub Surround (sq ft) | B27: SQFT | C27: 18 | D27: 0 | E27: =$C27*D27 -> 0 | F27: 0 | G27: =$C27*F27 -> 0 | H27: 0 | I27: =$C27*H27 -> 0
A28: 5-Piece Alcove Polystyrene Tub Surround | B28: LOT | C28: 350 | D28: 1 | E28: =$C28*D28 -> 350 | F28: 1 | G28: =$C28*F28 -> 350 | H28: 1 | I28: =$C28*H28 -> 350
A29: Back Splash (sq ft) - Kitchen and Vanity | B29: SQFT | C29: 18 | D29: 0 | E29: =$C29*D29 -> 0 | F29: 0 | G29: =$C29*F29 -> 0 | H29: 0 | I29: =$C29*H29 -> 0
A30: CABINETS | E30: =TEXT((SUM(E31:E35)),"$0,000.00") -> $5,415.00 | G30: =TEXT((SUM(G31:G35)),"$0,000.00") -> $7,335.00 | I30: =TEXT((SUM(I31:I35)),"$0,000.00") -> $6,935.00
A31: Kitchen Cabinets upper and lower (linear ft) | B31: LN FT | C31: 295 | D31: 12 | E31: =$C31*D31 -> 3540 | F31: 16 | G31: =$C31*F31 -> 4720 | H31: 16 | I31: =$C31*H31 -> 4720
A32: Kitchen Island | B32: Lot | C32: 1200 | D32: 0 | E32: =$C32*D32 -> 0 | F32: 0 | G32: =$C32*F32 -> 0 | H32: 0 | I32: =$C32*H32 -> 0
A33: Kitchen Counters (linear ft) | B33: LN FT | C33: 85 | D33: 12 | E33: =$C33*D33 -> 1020 | F33: 16 | G33: =$C33*F33 -> 1360 | H33: 16 | I33: =$C33*H33 -> 1360
A34: Bathroom Vanity (3 ft) | B34: EACH | C34: =855 -> 855 | D34: 1 | E34: =$C34*D34 -> 855 | F34: 0 | G34: =$C34*F34 -> 0 | H34: 1 | I34: =$C34*H34 -> 855
A35: Bathroom Vanity (>3 ft) | B35: EACH | C35: =1255 -> 1255 | D35: 0 | E35: =$C35*D35 -> 0 | F35: 1 | G35: =$C35*F35 -> 1255 | H35: 0 | I35: =$C35*H35 -> 0
A36: PLUMBING | E36: =TEXT((SUM(E37:E44)),"$0,000.00") -> $4,350.00 | G36: =TEXT((SUM(G37:G44)),"$0,000.00") -> $4,350.00 | I36: =TEXT((SUM(I37:I44)),"$0,000.00") -> $4,350.00
A37: Kitchen Sink - w/ p trap | B37: EACH | C37: 590 | D37: 1 | E37: =$C37*D37 -> 590 | F37: 1 | G37: =$C37*F37 -> 590 | H37: 1 | I37: =$C37*H37 -> 590
A38: Kitchen Faucet | B38: EACH | C38: 375 | D38: 1 | E38: =$C38*D38 -> 375 | F38: 1 | G38: =$C38*F38 -> 375 | H38: 1 | I38: =$C38*H38 -> 375
A39: New Tub | B39: EACH | C39: 1050 | D39: 1 | E39: =$C39*D39 -> 1050 | F39: 1 | G39: =$C39*F39 -> 1050 | H39: 1 | I39: =$C39*H39 -> 1050
A40: New Shower Valve and Trim Kit; includes Rough-in | B40: EACH | C40: 655 | D40: 1 | E40: =$C40*D40 -> 655 | F40: 1 | G40: =$C40*F40 -> 655 | H40: 1 | I40: =$C40*H40 -> 655
...

Sheet Pricing UNITS Combined
A1: PO Box 13012 Calgary RPO Beltline, AB T2R 1C6 info@luminovas.ca Phone: 587-320-0261
B2: UNITS | C2: QTY | D2: RATE | E2: TOTAL | F2: OUR COST | G2: PROFIT
A3: DRYWALL | E3: =TEXT((SUM(E4:E7)),"$0,000.00") -> $205,115.50 | F3: =TEXT((SUM(F4:F7)),"$0,000.00") -> $199,240.03 | G3: =TEXT((SUM(G4:G7)),"$0,000.00") -> $5,875.47
A4: up to 2 ft | B4: LN FT | C4: 5250 | D4: 18 | E4: =D4*C4 -> 94500 | F4: 92157 | G4: =E4-F4 -> 2343
A5: Float Wall to Flat Texture | B5: SQFT | C5: 59937 | D5: 1.5 | E5: =D5*C5 -> 89905.5 | F5: 87676.41 | G5: =E5-F5 -> 2229.09
A6: Drywalled Ceiling including Insulation Texture Ceiling | B6: SQFT | C6: 900 | D6: 6.9 | E6: =D6*C6 -> 6210 | F6: 5266.12 | G6: =E6-F6 -> 943.88
A7: Tub Surround Boarding | B7: EACH | C7: 29 | D7: 500 | E7: =D7*C7 -> 14500 | F7: 14140.5 | G7: =E7-F7 -> 359.5
A8: FINISHING | E8: =TEXT((SUM(E9:E21)),"$0,000.00") -> $145,977.00 | F8: =TEXT((SUM(F9:F21)),"$0,000.00") -> $97,628.52 | G8: =TEXT((SUM(G9:G12)),"$0,000.00") -> $4,350.00
A9: Doors | B9: EACH | C9: 0 | D9: 290 | E9: =D9*C9 -> 0 | G9: =E9-F9 -> 0
A10: New fire rated Entry Suite Door | B10: EACH | C10: 0 | D10: 1800 | E10: =D10*C10 -> 0 | G10: =E10-F10 -> 0
A11: Closet Shelves and Rod (Price per closet/storage room) | B11: EACH | C11: =84+29 -> 113 | D11: 180 | E11: =D11*C11 -> 20340 | F11: =3480+13380 -> 16860 | G11: =E11-F11 -> 3480
A12: Towel bar, toilet paper holder and shower rod | B12: EACH | C12: =29 -> 29 | D12: 190 | E12: =D12*C12 -> 5510 | F12: =(85+75)*29 -> 4640 | G12: =E12-F12 -> 870
A13: Closet Doors - Bypass upto 48"W and bifolds upto 36"W | B13: EACH | C13: 7 | D13: 350 | E13: =D13*C13 -> 2450 | F13: 1992.66 | G13: =E13-F13 -> 457.34
A14: Closet Doors - Bypass over 48"W - upto 60"W | B14: EACH | C14: 22 | D14: 480 | E14: =D14*C14 -> 10560 | F14: 8588.75 | G14: =E14-F14 -> 1971.25
A15: Closet Doors - Bypass over 60"W - upto 72"W | B15: EACH | C15: 22 | D15: 490 | E15: =D15*C15 -> 10780 | F15: 8767.69 | G15: =E15-F15 -> 2012.31
A16: Closet Doors - Bypass over 72"W - upto 96"W | B16: EACH | C16: 33 | D16: 525 | E16: =D16*C16 -> 17325 | F16: 14090.92 | G16: =E16-F16 -> 3234.08
A17: Suite Door Closer | B17: EACH | C17: 29 | D17: 110 | E17: =D17*C17 -> 3190 | F17: =50*29 -> 1450 | G17: =E17-F17 -> 1740
A18: Door Hardware (handle, hinges, and door stops) | B18: EACH | C18: =4*29 -> 116 | D18: 56 | E18: =D18*C18 -> 6496 | F18: =27*C18 -> 3132 | G18: =E18-F18 -> 3364
A19: Baseboards | B19: LN FT | C19: 7250 | D19: 4 | E19: =D19*C19 -> 29000 | F19: =1.1*C19+700*29/2 -> 18125 | G19: =E19-F19 -> 10875
A20: Window and Door Casing | B20: LN FT | C20: 9284 | D20: 4 | E20: =D20*C20 -> 37136 | F20: =0.85*C20+700*29/2 -> 18041.4 | G20: =E20-F20 -> 19094.6
A21: Mirror | B21: EACH | C21: 29 | D21: 110 | E21: =D21*C21 -> 3190 | F21: =66.9*C21 -> 1940.1 | G21: =E21-F21 -> 1249.9
A22: FLOORING | E22: =TEXT((SUM(E23:E25)),"$0,000.00") -> $112,569.60 | F22: =TEXT((SUM(F23:F25)),"$0,000.00") -> $85,001.26 | G22: =TEXT((SUM(G23:G25)),"$0,000.00") -> $27,568.34
A23: Floor Vinyl | B23: SQFT | C23: 12516 | D23: 4.85 | E23: =D23*C23 -> 60702.6 | F23: 45043.5 | G23: =E23-F23 -> 15659.1
A24: Removal of existing flooring and disposal | B24: SQFT | C24: 0 | D24: 0.75 | E24: =D24*C24 -> 0 | F24: =2850/2 -> 1425 | G24: =E24-F24 -> -1425
A25: Carpet with underlay | B25: SQFT | C25: 11526 | D25: 4.5 | E25: =D25*C25 -> 51867 | F25: 38532.76 | G25: =E25-F25 -> 13334.24
A26: TILING | E26: =TEXT((SUM(E27:E28)),"$0,000.00") -> $23,345.00 | F26: =TEXT((SUM(F27:F28)),"$0,000.00") -> $23,200.00 | G26: =TEXT((SUM(G27:G28)),"$0,000.00") -> $0,145.00
A27: Tile Tub Surround (sq ft) | B27: SQFT | C27: =70*29 -> 2030 | D27: 11.5 | E27: =D27*C27 -> 23345 | F27: =800*29 -> 23200 | G27: =E27-F27 -> 145
A28: Back Splash (sq ft) - Kitchen and Vanity | B28: SQFT | C28: 0 | D28: 11.5 | E28: =D28*C28 -> 0 | G28: =E28-F28 -> 0
A29: CABINETS | E29: =TEXT((SUM(E30:E32)),"$0,000.00") -> $189,515.00 | F29: =TEXT((SUM(F30:F32)),"$0,000.00") -> $132,500.00 | G29: =TEXT((SUM(G30:G32)),"$0,000.00") -> $57,015.00
A30: Kitchen Cabinets (upper & lower) (linear ft) | B30: LN FT | C30: =29*16 -> 464 | D30: 295 | E30: =D30*C30 -> 136880 | F30: 132500 | G30: =E30-F30 -> 4380
A31: Kitchen Counters (linear ft) | B31: LN FT | C31: =C30 -> 464 | D31: 60 | E31: =D31*C31 -> 27840 | G31: =E31-F31 -> 27840
A32: Bathroom Vanity (3 ft) | B32: EACH | C32: 29 | D32: 855 | E32: =D32*C32 -> 24795 | G32: =E32-F32 -> 24795
A33: PLUMBING | E33: =TEXT((SUM(E34:E42)),"$0,000.00") -> $92,930.00 | F33: =TEXT((SUM(F34:F42)),"$0,000.00") -> $68,975.95 | G33: =TEXT((SUM(G34:G42)),"$0,000.00") -> $23,954.05
A34: Kitchen Sink - w/ p trap | B34: EACH | C34: 29 | D34: 590 | E34: =D34*C34 -> 17110 | F34: 12670.287 | G34: =E34-F34 -> 4439.7131
A35: Shut off valves | B35: EACH | C35: =29*7 -> 203 | D35: 70 | E35: =D35*C35 -> 14210 | F35: 10522.781 | G35: =E35-F35 -> 3687.2194
A36: Kitchen Faucet | B36: EACH | C36: 29 | D36: 300 | E36: =D36*C36 -> 8700 | F36: 6442.5187 | G36: =E36-F36 -> 2257.4813
A37: Bathroom Sink - w/ p trap | B37: EACH | C37: 29 | D37: 325 | E37: =D37*C37 -> 9425 | F37: 6979.3953 | G37: =E37-F37 -> 2445.6047
A38: Bathroom Faucet | B38: EACH | C38: 29 | D38: 290 | E38: =D38*C38 -> 8410 | F38: 6227.7681 | G38: =E38-F38 -> 2182.2319
A39: New Tub | B39: EACH | C39: 0 | D39: 900 | E39: =D39*C39 -> 0 | F39: 0 | G39: =E39-F39 -> 0
A40: New Shower Valve and Trim Kit; includes Rough-in | B40: EACH | C40: 29 | D40: 585 | E40: =D40*C40 -> 16965 | F40: 12562.912 | G40: =E40-F40 -> 4402.0884
...

Sheet Price - Breakdown (A)
A1: PO Box 13012 Calgary RPO Beltline, AB T2R 1C6 info@luminovas.ca Phone: 587-320-0261
B2: UNITS | C2: QTY | D2: RATE | E2: TOTAL | F2: OUR COST | G2: PROFIT
A3: ABATEMENT | E3: =TEXT((SUM(E4)),"$0,000.00") -> $130,500.00 | F3: =TEXT((SUM(F4)),"$0,000.00") -> $115,250.00 | G3: =TEXT((SUM(G4)),"$0,000.00") -> $15,250.00
A4: Shower Surrounds, Damage Ceilings, and Kitchens as per scope | B4: UNITS | C4: 29 | D4: 4500 | E4: =D4*C4 -> 130500 | F4: 115250 | G4: =E4-F4 -> 15250
A5: DRYWALL | E5: =TEXT((SUM(E6:E9)),"$0,000.00") -> $204,305.50 | F5: =TEXT((SUM(F6:F9)),"$0,000.00") -> $199,240.03 | G5: =TEXT((SUM(G6:G9)),"$0,000.00") -> $5,065.47
A6: up to 2 ft | B6: LN FT | C6: 5250 | D6: 18 | E6: =D6*C6 -> 94500 | F6: 92157 | G6: =E6-F6 -> 2343
A7: Float Wall to Flat Texture | B7: SQFT | C7: 59937 | D7: 1.5 | E7: =D7*C7 -> 89905.5 | F7: 87676.41 | G7: =E7-F7 -> 2229.09
A8: Drywalled Ceiling including Insulation Texture Ceiling | B8: SQFT | C8: 900 | D8: 6 | E8: =D8*C8 -> 5400 | F8: 5266.12 | G8: =E8-F8 -> 133.88
A9: Tub Surround Boarding | B9: EACH | C9: 29 | D9: 500 | E9: =D9*C9 -> 14500 | F9: 14140.5 | G9: =E9-F9 -> 359.5
A10: FINISHING | E10: =TEXT((SUM(E11:E23)),"$0,000.00") -> $144,775.50 | F10: =TEXT((SUM(F11:F23)),"$0,000.00") -> $97,628.52 | G10: =TEXT((SUM(G11:G14)),"$0,000.00") -> $4,350.00
A11: Doors | B11: EACH | C11: 0 | D11: 310 | E11: =D11*C11 -> 0 | G11: =E11-F11 -> 0 | I11: 310
A12: New fire rated Entry Suite Door | B12: EACH | C12: 0 | D12: 1800 | E12: =D12*C12 -> 0 | G12: =E12-F12 -> 0 | I12: 1800
A13: Closet Shelves and Rod (Price per closet/storage room) | B13: EACH | C13: =84+29 -> 113 | D13: 180 | E13: =D13*C13 -> 20340 | F13: =3480+13380 -> 16860 | G13: =E13-F13 -> 3480 | I13: 180
A14: Towel bar, toilet paper holder and shower rod | B14: EACH | C14: =29 -> 29 | D14: 190 | E14: =D14*C14 -> 5510 | F14: =(85+75)*29 -> 4640 | G14: =E14-F14 -> 870 | I14: 190
A15: Closet Doors - Bypass upto 48"W and bifolds upto 36"W | B15: EACH | C15: 7 | D15: 350 | E15: =D15*C15 -> 2450 | F15: 1992.66 | G15: =E15-F15 -> 457.34 | I15: 350
A16: Closet Doors - Bypass over 48"W - upto 60"W | B16: EACH | C16: 22 | D16: 350 | E16: =D16*C16 -> 7700 | F16: 8588.75 | G16: =E16-F16 -> -888.75 | I16: 350
A17: Closet Doors - Bypass over 60"W - upto 72"W | B17: EACH | C17: 22 | D17: 350 | E17: =D17*C17 -> 7700 | F17: 8767.69 | G17: =E17-F17 -> -1067.69 | I17: 350
A18: Closet Doors - Bypass over 72"W - upto 96"W | B18: EACH | C18: 33 | D18: 350 | E18: =D18*C18 -> 11550 | F18: 14090.92 | G18: =E18-F18 -> -2540.92 | I18: 350
A19: Suite Door Closer | B19: EACH | C19: 29 | D19: 110 | E19: =D19*C19 -> 3190 | F19: =50*29 -> 1450 | G19: =E19-F19 -> 1740 | I19: 110
A20: Door Hardware (handle, hinges, and door stops) | B20: EACH | C20: =4*29 -> 116 | D20: 106 | E20: =D20*C20 -> 12296 | F20: =27*C20 -> 3132 | G20: =E20-F20 -> 9164 | I20: =65+35+6 -> 106
A21: Baseboards | B21: LN FT | C21: 7250 | D21: 4.25 | E21: =D21*C21 -> 30812.5 | F21: =1.1*C21+700*29/2 -> 18125 | G21: =E21-F21 -> 12687.5 | I21: 4.25
A22: Window and Door Casing | B22: LN FT | C22: 9284 | D22: 4.25 | E22: =D22*C22 -> 39457 | F22: =0.85*C22+700*29/2 -> 18041.4 | G22: =E22-F22 -> 21415.6 | I22: 4.25
A23: Mirror | B23: EACH | C23: 29 | D23: 130 | E23: =D23*C23 -> 3770 | F23: =66.9*C23 -> 1940.1 | G23: =E23-F23 -> 1829.9 | I23: 130
A24: FLOORING | E24: =TEXT((SUM(E25:E27)),"$0,000.00") -> $124,590.60 | F24: =TEXT((SUM(F25:F27)),"$0,000.00") -> $85,001.26 | G24: =TEXT((SUM(G25:G27)),"$0,000.00") -> $39,589.34
A25: Floor Vinyl | B25: SQFT | C25: 12516 | D25: 5.35 | E25: =D25*C25 -> 66960.6 | F25: 45043.5 | G25: =E25-F25 -> 21917.1 | I25: 5.35
A26: Removal of existing flooring and disposal | B26: SQFT | C26: 0 | D26: 0.75 | E26: =D26*C26 -> 0 | F26: =2850/2 -> 1425 | G26: =E26-F26 -> -1425 | I26: 0.75 | J26: *half of delivery fee
A27: Carpet with underlay | B27: SQFT | C27: 11526 | D27: 5 | E27: =D27*C27 -> 57630 | F27: 38532.76 | G27: =E27-F27 -> 19097.24 | I27: 5
A28: TILING | E28: =TEXT((SUM(E29:E30)),"$0,000.00") -> $23,345.00 | F28: =TEXT((SUM(F29:F30)),"$0,000.00") -> $23,200.00 | G28: =TEXT((SUM(G29:G30)),"$0,000.00") -> $0,145.00
A29: Tile Tub Surround (sq ft) | B29: SQFT | C29: =70*29 -> 2030 | D29: 11.5 | E29: =D29*C29 -> 23345 | F29: =800*29 -> 23200 | G29: =E29-F29 -> 145
A30: Back Splash (sq ft) - Kitchen and Vanity | B30: SQFT | C30: 0 | D30: 11.5 | E30: =D30*C30 -> 0 | G30: =E30-F30 -> 0
A31: CABINETS | E31: =TEXT((SUM(E32:E34)),"$0,000.00") -> $189,515.00 | F31: =TEXT((SUM(F32:F34)),"$0,000.00") -> $132,500.00 | G31: =TEXT((SUM(G32:G34)),"$0,000.00") -> $57,015.00
A32: Kitchen Cabinets (upper & lower) (linear ft) | B32: LN FT | C32: =29*16 -> 464 | D32: 295 | E32: =D32*C32 -> 136880 | F32: 132500 | G32: =E32-F32 -> 4380
A33: Kitchen Counters (linear ft) | B33: LN FT | C33: =C32 -> 464 | D33: 60 | E33: =D33*C33 -> 27840 | G33: =E33-F33 -> 27840
A34: Bathroom Vanity (3 ft) | B34: EACH | C34: 29 | D34: 855 | E34: =D34*C34 -> 24795 | G34: =E34-F34 -> 24795
A35: PLUMBING | E35: =TEXT((SUM(E36:E44)),"$0,000.00") -> $92,930.00 | F35: =TEXT((SUM(F36:F44)),"$0,000.00") -> $69,050.00 | G35: =TEXT((SUM(G36:G44)),"$0,000.00") -> $23,880.00
A36: Kitchen Sink - w/ p trap | B36: EACH | C36: 29 | D36: 590 | E36: =D36*C36 -> 17110 | F36: =29*(1100+1250) -> 68150 | G36: =E36-F36 -> -51040 | I36: 590
A37: Shut off valves | B37: EACH | C37: =29*7 -> 203 | D37: 70 | E37: =D37*C37 -> 14210 | G37: =E37-F37 -> 14210 | I37: 70
A38: Kitchen Faucet | B38: EACH | C38: 29 | D38: 300 | E38: =D38*C38 -> 8700 | G38: =E38-F38 -> 8700 | I38: 300
A39: Bathroom Sink - w/ p trap | B39: EACH | C39: 29 | D39: 325 | E39: =D39*C39 -> 9425 | G39: =E39-F39 -> 9425 | I39: 325
A40: Bathroom Faucet | B40: EACH | C40: 29 | D40: 290 | E40: =D40*C40 -> 8410 | G40: =E40-F40 -> 8410 | I40: 290
...
